Workbook
Name Slicer_Country__or_dependency: #N/A
Name Slicer_geographical_region: #N/A

Sheet Dashboard
B1: #VALUE!
D2: Select Attributes: | E2: Population

Sheet By Country
A1: Population Attributes By Country
A3: Row Labels | B3: Population 2026 | C3: Density (P/Km²) | D3: Land Area (Km²) | E3: Migrants (net) | F3: Fert. Rate | G3: Median Age | H3: Urban Population % | I3: Rural Population % | J3: World Share
A4: Afghanistan | B4: 45047069 | C4: 69 | D4: 652860 | E4: -53884 | F4: 4.56 | G4: 17.4 | H4: 0.269 | I4: 0.731 | J4: 0.0054
A5: Albania | B5: 2751025 | C5: 100 | D5: 27400 | E5: -22595 | F5: 1.32 | G5: 37.8 | H5: 0.716 | I5: 0.284 | J5: 0.0003
A6: Algeria | B6: 48028334 | C6: 20 | D6: 2381740 | E6: -28841 | F6: 2.62 | G6: 28.8 | H6: 0.748 | I6: 0.252 | J6: 0.0058
A7: American Samoa | B7: 45319 | C7: 227 | D7: 200 | E7: -1004 | F7: 2.22 | G7: 29.1 | H7: 0 | J7: 5.5e-06
A8: Andorra | B8: 83753 | C8: 178 | D8: 470 | E8: 751 | F8: 1.1 | G8: 44.2 | H8: 0.816 | I8: 0.184 | J8: 1e-05
A9: Angola | B9: 40215179 | C9: 32 | D9: 1246700 | E9: -4270 | F9: 4.89 | G9: 16.7 | H9: 0.694 | I9: 0.306 | J9: 0.0048
A10: Anguilla | B10: 14817 | C10: 165 | D10: 90 | E10: 33 | F10: 1.34 | G10: 39.1 | H10: 0 | J10: 1.8e-06
A11: Antigua and Barbuda | B11: 94626 | C11: 215 | D11: 440 | E11: -2 | F11: 1.57 | G11: 36.7 | H11: 0.286 | I11: 0.714 | J11: 1.1e-05
A12: Argentina | B12: 46003734 | C12: 17 | D12: 2736690 | E12: 2316 | F12: 1.51 | G12: 33.3 | H12: 0.965 | I12: 0.035 | J12: 0.0055
A13: Armenia | B13: 2930915 | C13: 103 | D13: 28470 | E13: -27000 | F13: 1.71 | G13: 37.2 | H13: 0.644 | I13: 0.356 | J13: 0.0004
A14: Aruba | B14: 108164 | C14: 601 | D14: 180 | E14: 73 | F14: 1.6 | G14: 41.7 | H14: 0.451 | I14: 0.549 | J14: 1.3e-05
A15: Australia | B15: 27227096 | C15: 4 | D15: 7682300 | E15: 131706 | F15: 1.64 | G15: 38.5 | H15: 0.867 | I15: 0.133 | J15: 0.0033
A16: Austria | B16: 9107266 | C16: 111 | D16: 82409 | E16: 13212 | F16: 1.34 | G16: 43.9 | H16: 0.59 | I16: 0.41 | J16: 0.0011
A17: Azerbaijan | B17: 10454855 | C17: 126 | D17: 82658 | E17: 7708 | F17: 1.66 | G17: 34.1 | H17: 0.591 | I17: 0.409 | J17: 0.0013
A18: Bahamas | B18: 404628 | C18: 40 | D18: 10010 | E18: 902 | F18: 1.36 | G18: 35.7 | H18: 0.889 | I18: 0.111 | J18: 4.9e-05
A19: Bahrain | B19: 1675572 | C19: 2205 | D19: 760 | E19: 14280 | F19: 1.77 | G19: 33.4 | H19: 0 | J19: 0.0002
A20: Bangladesh | B20: 177818044 | C20: 1366 | D20: 130170 | E20: -371398 | F20: 2.09 | G20: 26.3 | H20: 0.432 | I20: 0.568 | J20: 0.021
A21: Barbados | B21: 282724 | C21: 657 | D21: 430 | E21: -98 | F21: 1.71 | G21: 39.7 | H21: 0.327 | I21: 0.673 | J21: 3.4e-05
A22: Belarus | B22: 8937018 | C22: 44 | D22: 202910 | E22: -3608 | F22: 1.23 | G22: 41.8 | H22: 0.851 | I22: 0.149 | J22: 0.0011
A23: Belgium | B23: 11774642 | C23: 389 | D23: 30280 | E23: 29607 | F23: 1.4 | G23: 42.1 | H23: 0.99 | I23: 0.01 | J23: 0.0014
A24: Belize | B24: 428644 | C24: 19 | D24: 22810 | E24: 392 | F24: 1.99 | G24: 27.3 | H24: 0.49 | I24: 0.51 | J24: 5.2e-05
A25: Benin | B25: 15170419 | C25: 135 | D25: 112760 | E25: -6318 | F25: 4.34 | G25: 18.2 | H25: 0.484 | I25: 0.516 | J25: 0.0018
A26: Bermuda | B26: 64459 | C26: 1289 | D26: 50 | E26: -9 | F26: 1.42 | G26: 46.4 | H26: 0.93 | I26: 0.07 | J26: 7.8e-06
A27: Bhutan | B27: 802214 | C27: 21 | D27: 38117 | E27: 633 | F27: 1.43 | G27: 31 | H27: 0.511 | I27: 0.489 | J27: 9.7e-05
A28: Bolivia | B28: 12749291 | C28: 12 | D28: 1083300 | E28: -3157 | F28: 2.47 | G28: 25.5 | H28: 0.71 | I28: 0.29 | J28: 0.0015
A29: Bosnia and Herzegovina | B29: 3114242 | C29: 61 | D29: 51000 | E29: -7581 | F29: 1.5 | G29: 46.1 | H29: 0.571 | I29: 0.429 | J29: 0.0004
A30: Botswana | B30: 2603388 | C30: 5 | D30: 566730 | E30: -4169 | F30: 2.63 | G30: 23.7 | H30: 0.761 | I30: 0.239 | J30: 0.0003
A31: Brazil | B31: 213562666 | C31: 26 | D31: 8358140 | E31: -205642 | F31: 1.59 | G31: 35.3 | H31: 0.917 | I31: 0.083 | J31: 0.026
... A49: Congo | B49: 6637785 | C49: 19 | D49: 341500 | E49: -3298 | F49: 3.99 | G49: 18.7 | H49: 0.703 | I49: 0.297 | J49: 0.0008
A50: Cook Islands | B50: 12826 | C50: 53 | D50: 240 | E50: -419 | F50: 1.98 | G50: 38.1 | H50: 0 | J50: 1.5e-06
A51: Costa Rica | B51: 5174789 | C51: 101 | D51: 51060 | E51: 966 | F51: 1.31 | G51: 35.7 | H51: 0.859 | I51: 0.141 | J51: 0.0006
A52: Côte d'Ivoire | B52: 33494346 | C52: 105 | D52: 318000 | E52: 6535 | F52: 4.1 | G52: 18.5 | H52: 0.495 | I52: 0.505 | J52: 0.004
A53: Croatia | B53: 3822345 | C53: 68 | D53: 55960 | E53: -2491 | F53: 1.47 | G53: 45.5 | H53: 0.622 | I53: 0.378 | J53: 0.0005
A54: Cuba | B54: 10892659 | C54: 102 | D54: 106440 | E54: -22086 | F54: 1.46 | G54: 42.5 | H54: 0.824 | I54: 0.176 | J54: 0.0013
A55: Curaçao | B55: 185440 | C55: 418 | D55: 444 | E55: 462 | F55: 1.07 | G55: 39 | H55: 0.812 | I55: 0.188 | J55: 2.2e-05
A56: Cyprus | B56: 1382334 | C56: 150 | D56: 9240 | E56: 7210 | F56: 1.37 | G56: 39.1 | H56: 0.611 | I56: 0.389 | J56: 0.0002
A57: Czech Republic (Czechia) | B57: 10527781 | C57: 136 | D57: 77240 | E57: 13400 | F57: 1.47 | G57: 44.3 | H57: 0.757 | I57: 0.243 | J57: 0.0013
A58: Denmark | B58: 6023520 | C58: 142 | D58: 42430 | E58: 18360 | F58: 1.52 | G58: 41.3 | H58: 0.876 | I58: 0.124 | J58: 0.0007
...

Sheet Pivot Tables
B2: Most Populated Country | E2: Least Populated Country | H2: Number of Countries | R2: Growth Rate | U2: Current World Population | X2: Density (P/Km²) | AA2: Land Area (Km²) | AU2: Median Age | AX2: Fertility Rate
B3: =B17 -> India | C3: =MAX(C8:C17) -> 1476625576 | E3: =E17 -> Holy See | F3: =MIN(F8:F17) -> 506 | H3: =COUNTA(H8:H1048576) -> 234 | R3: =GETPIVOTDATA("[Measures].[Sum of Yearly Growth Rate]",$R$7,"[Yearly Population Growth Rate].[Year]","[Yearly Population Growth Rate].[Year].&[2026]") -> 0.0084 | U3: =MAX(V:V) -> 8300678395 | X3: =GETPIVOTDATA("[Measures].[Sum of Density (P/Km²) 3]",$X$7,"[World Population by Year].[Year]","[World Population by Year].[Year].&[2026]") -> 56 | AA3: =GETPIVOTDATA("[Measures].[Sum of Land Area (Km²) 2]",$AA$7) -> 130094010 | AU3: =GETPIVOTDATA("[Measures].[Sum of Median Age]",$AU$7,"[World Population 2025 and Historical].[Year (July 1)]","[World Population 2025 and Historical].[Year (July 1)].&[2026]") -> 31.1 | AX3: =GETPIVOTDATA("[Measures].[Sum of Fertility Rate]",$AX$7,"[World Population 2025 and Historical].[Year (July 1)]","[World Population 2025 and Historical].[Year (July 1)].&[2026]") -> 2.23
B6: Top 5 Countries with Largest Population | E6: Top 5 Countries with Lowest Population | H6: Population By Country | R6: Yearly Growth Rate | U6: World Population by Year | AD6: Population By Region | AJ6: Population By Religion | AM6: World Population Forecast (2030-2050) | AQ6: Population Growth Rate | AU6: Median Age | AX6: Fertility Rate
B7: Country | C7: Population | E7: Country | F7: Population | H7: Country | I7: Population | J7: Density (P/Km²) | K7: Land Area (Km²) | L7: Fert. Rate | M7: Median Age | N7: Urban Population % | O7: Rural Population % | P7: World Share | R7: Year | S7: Yearly Growth Rate | U7: Year | V7: Sum of Population | X7: Year | Y7: Density (P/Km²) | AA7: Region | AB7: Land Area (Km²) | AD7: Region | AE7: Population | AF7: Density (P/Km²) | AG7: Land Area (Km²) | AJ7: Religion | AK7: Percentage of the global population | AM7: Year | AN7: Population | AO7: Yearly % Change | AQ7: Year | AR7: Population | AS7: Yearly % Change | AU7: Year | AV7: Median Age | AX7: Year | AY7: Fertility Rate
B8: Ethiopia | C8: 138902185 | E8: Saint Barthelemy | F8: 11550 | H8: Afghanistan | I8: 45047069 | J8: 69 | K8: 652860 | L8: 4.56 | M8: 17.4 | N8: 0.269 | O8: 0.731 | P8: 0.0054 | R8: 2026 | S8: 0.0084 | U8: 2026 | V8: 8300678395 | X8: 2026 | Y8: 56 | AA8: Africa | AB8: 29648481 | AD8: Africa | AE8: 1584985259 | AF8: 53 | AG8: 29648481 | AJ8: Christians | AK8: 0.31514134 | AM8: 2030 | AN8: 8569124911 | AO8: 0.0081 | AQ8: 1955 | AR8: 2740213792 | AS8: 0.0191 | AU8: 2026 | AV8: 31.1 | AX8: 2026 | AY8: 2.23
B9: Russia | C9: 143394458 | E9: Wallis & Futuna | F9: 11113 | H9: Albania | I9: 2751025 | J9: 100 | K9: 27400 | L9: 1.32 | M9: 37.8 | N9: 0.716 | O9: 0.284 | P9: 0.0003 | R9: 2025 | S9: 0.0085 | U9: 2025 | V9: 8231613070 | X9: 2025 | Y9: 55 | AA9: Asia | AB9: 31033131 | AD9: Asia | AE9: 4863327397 | AF9: 157 | AG9: 31033131 | AJ9: Muslims | AK9: 0.23180619 | AM9: 2035 | AN9: 8885210181 | AO9: 0.0073 | AQ9: 1960 | AR9: 3015470894 | AS9: 0.0193 | AU9: 2025 | AV9: 30.9 | AX9: 2025 | AY9: 2.24
B10: Bangladesh | C10: 177818044 | E10: Tuvalu | F10: 9362 | H10: Algeria | I10: 48028334 | J10: 20 | K10: 2381740 | L10: 2.62 | M10: 28.8 | N10: 0.748 | O10: 0.252 | P10: 0.0058 | R10: 2024 | S10: 0.0087 | U10: 2024 | V10: 8161972572 | X10: 2024 | Y10: 55 | AA10: Europe | AB10: 22134900 | AD10: Europe | AE10: 743482361 | AF10: 34 | AG10: 22134900 | AJ10: None | AK10: 0.16335817 | AM10: 2040 | AN10: 9177190203 | AO10: 0.0065 | AQ10: 1965 | AR10: 3334533703 | AS10: 0.0203 | AU10: 2024 | AV10: 30.6 | AX10: 2024 | AY10: 2.25
B11: Brazil | C11: 213562666 | E11: Saint Pierre & Miquelon | F11: 5513 | H11: American Samoa | I11: 45319 | J11: 227 | K11: 200 | L11: 2.22 | M11: 29.1 | N11: 0 | P11: 5.5e-06 | R11: 2023 | S11: 0.0088 | U11: 2023 | V11: 8091734930 | X11: 2023 | Y11: 54 | AA11: Latin America and the Caribbean | AB11: 20139378 | AD11: Latin America and the Caribbean | AE11: 672135561 | AF11: 33 | AG11: 20139378 | AJ11: Hindus | AK11: 0.14981097 | AM11: 2045 | AN11: 9439639668 | AO11: 0.0057 | AQ11: 1970 | AR11: 3694683794 | AS11: 0.0207 | AU11: 2023 | AV11: 30.4 | AX11: 2023 | AY11: 2.25
B12: Nigeria | C12: 242431832 | E12: Saint Helena | F12: 5147 | H12: Andorra | I12: 83753 | J12: 178 | K12: 470 | L12: 1.1 | M12: 44.2 | N12: 0.816 | O12: 0.184 | P12: 1e-05 | R12: 2022 | S12: 0.0084 | U12: 2022 | V12: 8021407192 | X12: 2022 | Y12: 54 | AA12: Northern America | AB12: 18651660 | AD12: Northern America | AE12: 389628823 | AF12: 21 | AG12: 18651660 | AJ12: Buddhists | AK12: 0.070700084 | AM12: 2050 | AN12: 9664378587 | AO12: 0.0047 | AQ12: 1975 | AR12: 4070735277 | AS12: 0.0196 | AU12: 2022 | AV12: 30.1 | AX12: 2022 | AY12: 2.27
B13: Pakistan | C13: 259299791 | E13: Montserrat | F13: 4328 | H13: Angola | I13: 40215179 | J13: 32 | K13: 1246700 | L13: 4.89 | M13: 16.7 | N13: 0.694 | O13: 0.306 | P13: 0.0048 | R13: 2021 | S13: 0.0086 | U13: 2021 | V13: 7954448391 | X13: 2021 | Y13: 53 | AA13: Oceania | AB13: 8486460 | AD13: Oceania | AE13: 47118993 | AF13: 6 | AG13: 8486460 | AJ13: Folk Religionists | AK13: 0.058748037 | AQ13: 1980 | AR13: 4447606236 | AS13: 0.0179 | AU13: 2021 | AV13: 29.8 | AX13: 2021 | AY13: 2.29
B14: Indonesia | C14: 287886782 | E14: Falkland Islands | F14: 3465 | H14: Anguilla | I14: 14817 | J14: 165 | K14: 90 | L14: 1.34 | M14: 39.1 | N14: 0 | P14: 1.8e-06 | R14: 2020 | S14: 0.0097 | U14: 2020 | V14: 7887001292 | X14: 2020 | Y14: 53 | AA14: Grand Total | AB14: 130094010 | AJ14: Other Religions | AK14: 0.0084267585 | AQ14: 1985 | AR14: 4868943465 | AS14: 0.0183 | AU14: 2020 | AV14: 29.6 | AX14: 2020 | AY14: 2.32
B15: United States | C15: 349035494 | E15: Tokelau | F15: 2691 | H15: Antigua and Barbuda | I15: 94626 | J15: 215 | K15: 440 | L15: 1.57 | M15: 36.7 | N15: 0.286 | O15: 0.714 | P15: 1.1e-05 | R15: 2019 | S15: 0.0105 | U15: 2019 | V15: 7811293698 | X15: 2019 | Y15: 52 | AD15: Urban and Rural Population by Region | AJ15: Jews | AK15: 0.0020084427 | AQ15: 1990 | AR15: 5327803110 | AS15: 0.0182 | AU15: 2015 | AV15: 28.3 | AX15: 2015 | AY15: 2.54
B16: China | C16: 1412914089 | E16: Niue | F16: 1822 | H16: Argentina | I16: 46003734 | J16: 17 | K16: 2736690 | L16: 1.51 | M16: 33.3 | N16: 0.965 | O16: 0.035 | P16: 0.0055 | R16: 2018 | S16: 0.011 | U16: 2018 | V16: 7729902781 | X16: 2018 | Y16: 52 | AD16: Region | AE16: Urban Population % | AF16: Rural Population % | AQ16: 1995 | AR16: 5758878982 | AS16: 0.0157 | AU16: 2010 | AV16: 27.2 | AX16: 2010 | AY16: 2.6
B17: India | C17: 1476625576 | E17: Holy See | F17: 506 | H17: Armenia | I17: 2930915 | J17: 103 | K17: 28470 | L17: 1.71 | M17: 37.2 | N17: 0.644 | O17: 0.356 | P17: 0.0004 | R17: 2017 | S17: 0.0115 | U17: 2017 | V17: 7645617954 | X17: 2017 | Y17: 51 | AD17: Africa | AE17: 0.456 | AF17: 0.544 | AJ17: {=AJ7:AK15} -> Religion | AK17: Percentage of the global population | AQ17: 2000 | AR17: 6171702993 | AS17: 0.0139 | AU17: 2005 | AV17: 26.1 | AX17: 2005 | AY17: 2.63
H18: Aruba | I18: 108164 | J18: 601 | K18: 180 | L18: 1.6 | M18: 41.7 | N18: 0.451 | O18: 0.549 | P18: 1.3e-05 | R18: 2016 | S18: 0.0118 | U18: 2016 | V18: 7558554526 | X18: 2016 | Y18: 51 | AD18: Asia | AE18: 0.541 | AF18: 0.459 | AJ18: Christians | AK18: 0.31514134 | AQ18: 2005 | AR18: 6586970132 | AS18: 0.0131 | AU18: 2000 | AV18: 25.1 | AX18: 2000 | AY18: 2.75
H19: Australia | I19: 27227096 | J19: 4 | K19: 7682300 | L19: 1.64 | M19: 38.5 | N19: 0.867 | O19: 0.133 | P19: 0.0033 | R19: 2015 | S19: 0.012 | U19: 2015 | V19: 7470491872 | X19: 2015 | Y19: 50 | AD19: Europe | AE19: 0.762 | AF19: 0.238 | AJ19: Muslims | AK19: 0.23180619 | AQ19: 2010 | AR19: 7021732148 | AS19: 0.0129 | AU19: 1995 | AV19: 24 | AX19: 1995 | AY19: 2.89
H20: Austria | I20: 9107266 | J20: 111 | K20: 82409 | L20: 1.34 | M20: 43.9 | N20: 0.59 | O20: 0.41 | P20: 0.0011 | R20: 2014 | S20: 0.0123 | U20: 2014 | V20: 7381616244 | X20: 2014 | Y20: 50 | AD20: Latin America and the Caribbean | AE20: 0.859 | AF20: 0.141 | AJ20: None | AK20: 0.16335817 | AQ20: 2015 | AR20: 7470491872 | AS20: 0.0125 | AU20: 1990 | AV20: 22.9 | AX20: 1990 | AY20: 3.31
H21: Azerbaijan | I21: 10454855 | J21: 126 | K21: 82658 | L21: 1.66 | M21: 34.1 | N21: 0.591 | O21: 0.409 | P21: 0.0013 | R21: 2013 | S21: 0.0126 | U21: 2013 | V21: 7291793585 | X21: 2013 | Y21: 49 | AD21: Northern America | AE21: 0.828 | AF21: 0.172 | AJ21: Hindus | AK21: 0.14981097 | AQ21: 2020 | AR21: 7887001292 | AS21: 0.0109 | AU21: 1985 | AV21: 22 | AX21: 1985 | AY21: 3.52
H22: Bahamas | I22: 404628 | J22: 40 | K22: 10010 | L22: 1.36 | M22: 35.7 | N22: 0.889 | O22: 0.111 | P22: 4.9e-05 | R22: 2012 | S22: 0.0127 | U22: 2012 | V22: 7201202485 | X22: 2012 | Y22: 48 | AD22: Oceania | AE22: 0.663 | AF22: 0.337 | AJ22: Buddhists | AK22: 0.070700084 | AQ22: 2021 | AR22: 7954448391 | AS22: 0.0086 | AU22: 1980 | AV22: 21.5 | AX22: 1980 | AY22: 3.74
H23: Bahrain | I23: 1675572 | J23: 2205 | K23: 760 | L23: 1.77 | M23: 33.4 | N23: 0 | P23: 0.0002 | R23: 2011 | S23: 0.0127 | U23: 2011 | V23: 7110923765 | X23: 2011 | Y23: 48 | AJ23: Folk Religionists | AK23: 0.058748037 | AQ23: 2022 | AR23: 8021407192 | AS23: 0.0084 | AU23: 1975 | AV23: 20.7 | AX23: 1975 | AY23: 4.08
H24: Bangladesh | I24: 177818044 | J24: 1366 | K24: 130170 | L24: 2.09 | M24: 26.3 | N24: 0.432 | O24: 0.568 | P24: 0.021 | R24: 2010 | S24: 0.0128 | U24: 2010 | V24: 7021732148 | X24: 2010 | Y24: 47 | AD24: World Share | AJ24: Other Religions | AK24: 0.0084267585 | AQ24: 2023 | AR24: 8091734930 | AS24: 0.0088 | AU24: 1970 | AV24: 20.3 | AX24: 1970 | AY24: 4.83
H25: Barbados | I25: 282724 | J25: 657 | K25: 430 | L25: 1.71 | M25: 39.7 | N25: 0.327 | O25: 0.673 | P25: 3.4e-05 | R25: 2009 | S25: 0.0129 | U25: 2009 | V25: 6932766416 | X25: 2009 | Y25: 47 | AD25: Region | AE25: World Share | AJ25: Jews | AK25: 0.0020084427 | AQ25: 2024 | AR25: 8161972572 | AS25: 0.0087 | AU25: 1965 | AV25: 20.8 | AX25: 1965 | AY25: 5.07
H26: Belarus | I26: 8937018 | J26: 44 | K26: 202910 | L26: 1.23 | M26: 41.8 | N26: 0.851 | O26: 0.149 | P26: 0.0011 | R26: 2008 | S26: 0.0129 | U26: 2008 | V26: 6844457662 | X26: 2008 | Y26: 46 | AD26: Africa | AE26: 0.191 | AQ26: 2025 | AR26: 8231613070 | AS26: 0.0085 | AU26: 1960 | AV26: 21.5 | AX26: 1960 | AY26: 4.7
H27: Belgium | I27: 11774642 | J27: 389 | K27: 30280 | L27: 1.4 | M27: 42.1 | N27: 0.99 | O27: 0.01 | P27: 0.0014 | R27: 2007 | S27: 0.0129 | U27: 2007 | V27: 6757308781 | X27: 2007 | Y27: 45 | AD27: Asia | AE27: 0.586 | AQ27: 2026 | AR27: 8300678395 | AS27: 0.0084 | AU27: 1955 | AV27: 21.8 | AX27: 1955 | AY27: 5
H28: Belize | I28: 428644 | J28: 19 | K28: 22810 | L28: 1.99 | M28: 27.3 | N28: 0.49 | O28: 0.51 | P28: 5.2e-05 | R28: 2006 | S28: 0.0128 | U28: 2006 | V28: 6671452015 | X28: 2006 | Y28: 45 | AD28: Europe | AE28: 0.09
H29: Benin | I29: 15170419 | J29: 135 | K29: 112760 | L29: 4.34 | M29: 18.2 | N29: 0.484 | O29: 0.516 | P29: 0.0018 | R29: 2005 | S29: 0.0129 | U29: 2005 | V29: 6586970132 | X29: 2005 | Y29: 44 | AD29: Latin America and the Caribbean | AE29: 0.081
H30: Bermuda | I30: 64459 | J30: 1289 | K30: 50 | L30: 1.42 | M30: 46.4 | N30: 0.93 | O30: 0.07 | P30: 7.8e-06 | R30: 2004 | S30: 0.0129 | U30: 2004 | V30: 6503377772 | X30: 2004 | Y30: 44 | AD30: Northern America | AE30: 0.047
H31: Bhutan | I31: 802214 | J31: 21 | K31: 38117 | L31: 1.43 | M31: 31 | N31: 0.511 | O31: 0.489 | P31: 9.7e-05 | R31: 2003 | S31: 0.013 | U31: 2003 | V31: 6420361634 | X31: 2003 | Y31: 43 | AD31: Oceania | AE31: 0.0057
H32: Bolivia | I32: 12749291 | J32: 12 | K32: 1083300 | L32: 2.47 | M32: 25.5 | N32: 0.71 | O32: 0.29 | P32: 0.0015 | R32: 2002 | S32: 0.0132 | U32: 2002 | V32: 6337730342 | X32: 2002 | Y32: 43
H33: Bosnia and Herzegovina | I33: 3114242 | J33: 61 | K33: 51000 | L33: 1.5 | M33: 46.1 | N33: 0.571 | O33: 0.429 | P33: 0.0004 | R33: 2001 | S33: 0.0135 | U33: 2001 | V33: 6254936459 | X33: 2001 | Y33: 42
H34: Botswana | I34: 2603388 | J34: 5 | K34: 566730 | L34: 2.63 | M34: 23.7 | N34: 0.761 | O34: 0.239 | P34: 0.0003 | R34: 2000 | S34: 0.0136 | U34: 2000 | V34: 6171702993 | X34: 2000 | Y34: 41
H35: Brazil | I35: 213562666 | J35: 26 | K35: 8358140 | L35: 1.59 | M35: 35.3 | N35: 0.917 | O35: 0.083 | P35: 0.026 | R35: 1999 | S35: 0.0136 | U35: 1999 | V35: 6089006339 | X35: 1999 | Y35: 41
H36: British Virgin Islands | I36: 39936 | J36: 266 | K36: 150 | L36: 1.06 | M36: 39.1 | N36: 0.439 | O36: 0.561 | P36: 4.8e-06 | R36: 1998 | S36: 0.0139 | U36: 1998 | V36: 6007066690 | X36: 1998 | Y36: 40
H37: Brunei | I37: 469775 | J37: 89 | K37: 5270 | L37: 1.7 | M37: 33.2 | N37: 0.806 | O37: 0.194 | P37: 5.7e-05 | R37: 1997 | S37: 0.0142 | U37: 1997 | V37: 5924787816 | X37: 1997 | Y37: 40
H38: Bulgaria | I38: 6667659 | J38: 61 | K38: 108560 | L38: 1.74 | M38: 45 | N38: 0.774 | O38: 0.226 | P38: 0.0008 | R38: 1996 | S38: 0.0144 | U38: 1996 | V38: 5842055734 | X38: 1996 | Y38: 39
H39: Burkina Faso | I39: 24601700 | J39: 90 | K39: 273600 | L39: 3.92 | M39: 18 | N39: 0.345 | O39: 0.655 | P39: 0.003 | R39: 1995 | S39: 0.0147 | U39: 1995 | V39: 5758878982 | X39: 1995 | Y39: 39
H40: Burundi | I40: 14729157 | J40: 574 | K40: 25680 | L40: 4.57 | M40: 16.6 | N40: 0.154 | O40: 0.846 | P40: 0.0018 | R40: 1994 | S40: 0.015 | U40: 1994 | V40: 5675551255 | X40: 1994 | Y40: 38
H41: Cabo Verde | I41: 529630 | J41: 131 | K41: 4030 | L41: 1.49 | M41: 29.5 | N41: 0.796 | O41: 0.204 | P41: 6.4e-05 | R41: 1993 | S41: 0.0155 | U41: 1993 | V41: 5591544797 | X41: 1993 | Y41: 38
H42: Cambodia | I42: 18051219 | J42: 102 | K42: 176520 | L42: 2.49 | M42: 26.4 | N42: 0.269 | O42: 0.731 | P42: 0.0022 | R42: 1992 | S42: 0.0161 | U42: 1992 | V42: 5505989816 | X42: 1992 | Y42: 37
H43: Cameroon | I43: 30640817 | J43: 65 | K43: 472710 | L43: 4.12 | M43: 18.2 | N43: 0.598 | O43: 0.402 | P43: 0.0037 | R43: 1991 | S43: 0.0171 | U43: 1991 | V43: 5418735891 | X43: 1991 | Y43: 36
...

Sheet Reference of Region Map
A1: Attributes | B1: Region | C1: Values | E1: List | H1: X | I1: Y | J1: Region | K1: Values | N1: List of Countries
A2: Population | B2: Africa | C2: =_xlfn.XLOOKUP(B2,'Pivot Tables'!$AD$8:$AD$13,'Pivot Tables'!$AE$8:$AE$13) -> 1584985259 | E2: Population | H2: 5.1 | I2: 4.7 | J2: Africa | K2: =SUMIFS($C$2:$C$19,$B$2:$B$19,J2,$A$2:$A$19,Dashboard!$E$2) -> 1584985259 | N2: Afghanistan
A3: Population | B3: Asia | C3: =_xlfn.XLOOKUP(B3,'Pivot Tables'!$AD$8:$AD$13,'Pivot Tables'!$AE$8:$AE$13) -> 4863327397 | E3: Density (P/Km²) | H3: 7 | I3: 7 | J3: Asia | K3: =SUMIFS($C$2:$C$19,$B$2:$B$19,J3,$A$2:$A$19,Dashboard!$E$2) -> 4863327397 | N3: Albania
A4: Population | B4: Europe | C4: =_xlfn.XLOOKUP(B4,'Pivot Tables'!$AD$8:$AD$13,'Pivot Tables'!$AE$8:$AE$13) -> 743482361 | E4: Land Area (Km²) | H4: 5 | I4: 7.2 | J4: Europe | K4: =SUMIFS($C$2:$C$19,$B$2:$B$19,J4,$A$2:$A$19,Dashboard!$E$2) -> 743482361 | N4: Algeria
A5: Population | B5: Latin America and the Caribbean | C5: =_xlfn.XLOOKUP(B5,'Pivot Tables'!$AD$8:$AD$13,'Pivot Tables'!$AE$8:$AE$13) -> 672135561 | E5: Fert. Rate | H5: 2.8 | I5: 3.5 | J5: Latin America and the Caribbean | K5: =SUMIFS($C$2:$C$19,$B$2:$B$19,J5,$A$2:$A$19,Dashboard!$E$2) -> 672135561 | N5: American Samoa
A6: Population | B6: Northern America | C6: =_xlfn.XLOOKUP(B6,'Pivot Tables'!$AD$8:$AD$13,'Pivot Tables'!$AE$8:$AE$13) -> 389628823 | E6: Urban Pop % | H6: 1.5 | I6: 7 | J6: Northern America | K6: =SUMIFS($C$2:$C$19,$B$2:$B$19,J6,$A$2:$A$19,Dashboard!$E$2) -> 389628823 | N6: Andorra
A7: Population | B7: Oceania | C7: =_xlfn.XLOOKUP(B7,'Pivot Tables'!$AD$8:$AD$13,'Pivot Tables'!$AE$8:$AE$13) -> 47118993 | E7: Rural Pop % | H7: 8.4 | I7: 2.5 | J7: Oceania | K7: =SUMIFS($C$2:$C$19,$B$2:$B$19,J7,$A$2:$A$19,Dashboard!$E$2) -> 47118993 | N7: Angola
A8: Density (P/Km²) | B8: Africa | C8: =_xlfn.XLOOKUP(B8,'Pivot Tables'!$AD$8:$AD$13,'Pivot Tables'!$AF$8:$AF$13) -> 53 | N8: Anguilla
A9: Density (P/Km²) | B9: Asia | C9: =_xlfn.XLOOKUP(B9,'Pivot Tables'!$AD$8:$AD$13,'Pivot Tables'!$AF$8:$AF$13) -> 157 | N9: Antigua And Barbuda
A10: Density (P/Km²) | B10: Europe | C10: =_xlfn.XLOOKUP(B10,'Pivot Tables'!$AD$8:$AD$13,'Pivot Tables'!$AF$8:$AF$13) -> 34 | N10: Argentina
A11: Density (P/Km²) | B11: Latin America and the Caribbean | C11: =_xlfn.XLOOKUP(B11,'Pivot Tables'!$AD$8:$AD$13,'Pivot Tables'!$AF$8:$AF$13) -> 33 | N11: Armenia
A12: Density (P/Km²) | B12: Northern America | C12: =_xlfn.XLOOKUP(B12,'Pivot Tables'!$AD$8:$AD$13,'Pivot Tables'!$AF$8:$AF$13) -> 21 | N12: Aruba
A13: Density (P/Km²) | B13: Oceania | C13: =_xlfn.XLOOKUP(B13,'Pivot Tables'!$AD$8:$AD$13,'Pivot Tables'!$AF$8:$AF$13) -> 6 | N13: Australia
A14: Land Area (Km²) | B14: Africa | C14: =_xlfn.XLOOKUP(B14,'Pivot Tables'!$AD$8:$AD$13,'Pivot Tables'!$AG$8:$AG$13) -> 29648481 | N14: Austria
A15: Land Area (Km²) | B15: Asia | C15: =_xlfn.XLOOKUP(B15,'Pivot Tables'!$AD$8:$AD$13,'Pivot Tables'!$AG$8:$AG$13) -> 31033131 | N15: Azerbaijan
A16: Land Area (Km²) | B16: Europe | C16: =_xlfn.XLOOKUP(B16,'Pivot Tables'!$AD$8:$AD$13,'Pivot Tables'!$AG$8:$AG$13) -> 22134900 | N16: Bahamas
A17: Land Area (Km²) | B17: Latin America and the Caribbean | C17: =_xlfn.XLOOKUP(B17,'Pivot Tables'!$AD$8:$AD$13,'Pivot Tables'!$AG$8:$AG$13) -> 20139378 | N17: Bahrain
A18: Land Area (Km²) | B18: Northern America | C18: =_xlfn.XLOOKUP(B18,'Pivot Tables'!$AD$8:$AD$13,'Pivot Tables'!$AG$8:$AG$13) -> 18651660 | N18: Bangladesh
A19: Land Area (Km²) | B19: Oceania | C19: =_xlfn.XLOOKUP(B19,'Pivot Tables'!$AD$8:$AD$13,'Pivot Tables'!$AG$8:$AG$13) -> 8486460 | N19: Barbados
N20: Belarus
N21: Belgium
N22: Belize
N23: Benin
N24: Bermuda
N25: Bhutan
N26: Bolivia
N27: Bosnia And Herzegovina
N28: Botswana
N29: Brazil
N30: British Virgin Islands
N31: Brunei
... N235: Zimbabwe
